[2022-07-22 07:31:35,462] {taskinstance.py:1179} INFO - Dependencies all met for <TaskInstance: etl.get_data manual__2022-07-22T07:31:34.540711+00:00 [queued]>
[2022-07-22 07:31:35,468] {taskinstance.py:1179} INFO - Dependencies all met for <TaskInstance: etl.get_data manual__2022-07-22T07:31:34.540711+00:00 [queued]>
[2022-07-22 07:31:35,469] {taskinstance.py:1376} INFO - 
--------------------------------------------------------------------------------
[2022-07-22 07:31:35,470] {taskinstance.py:1377} INFO - Starting attempt 1 of 1
[2022-07-22 07:31:35,470] {taskinstance.py:1378} INFO - 
--------------------------------------------------------------------------------
[2022-07-22 07:31:35,478] {taskinstance.py:1397} INFO - Executing <Task(_PythonDecoratedOperator): get_data> on 2022-07-22 07:31:34.540711+00:00
[2022-07-22 07:31:35,481] {standard_task_runner.py:52} INFO - Started process 12778 to run task
[2022-07-22 07:31:35,484] {standard_task_runner.py:79} INFO - Running: ['***', 'tasks', 'run', 'etl', 'get_data', 'manual__2022-07-22T07:31:34.540711+00:00', '--job-id', '41', '--raw', '--subdir', 'DAGS_FOLDER/pipeline_2.py', '--cfg-path', '/tmp/tmphqhi8qub', '--error-file', '/tmp/tmp6zr6k3f7']
[2022-07-22 07:31:35,485] {standard_task_runner.py:80} INFO - Job 41: Subtask get_data
[2022-07-22 07:31:35,523] {task_command.py:371} INFO - Running <TaskInstance: etl.get_data manual__2022-07-22T07:31:34.540711+00:00 [running]> on host b51f0a1d5848
[2022-07-22 07:31:35,559] {taskinstance.py:1591} INFO - Exporting the following env vars:
AIRFLOW_CTX_DAG_OWNER=***
AIRFLOW_CTX_DAG_ID=etl
AIRFLOW_CTX_TASK_ID=get_data
AIRFLOW_CTX_EXECUTION_DATE=2022-07-22T07:31:34.540711+00:00
AIRFLOW_CTX_TRY_NUMBER=1
AIRFLOW_CTX_DAG_RUN_ID=manual__2022-07-22T07:31:34.540711+00:00
[2022-07-22 07:31:35,676] {base.py:68} INFO - Using connection ID 'pg' for task execution.
[2022-07-22 07:31:35,688] {taskinstance.py:1909} ERROR - Task failed with exception
Traceback (most recent call last):
  File "/home/airflow/.local/lib/python3.7/site-packages/airflow/decorators/base.py", line 179, in execute
    return_value = super().execute(context)
  File "/home/airflow/.local/lib/python3.7/site-packages/airflow/operators/python.py", line 171, in execute
    return_value = self.execute_callable()
  File "/home/airflow/.local/lib/python3.7/site-packages/airflow/operators/python.py", line 189, in execute_callable
    return self.python_callable(*self.op_args, **self.op_kwargs)
  File "/opt/airflow/dags/pipeline_2.py", line 43, in get_data
    file
psycopg2.errors.BadCopyFileFormat: extra data after last expected column
CONTEXT:  COPY employees_temp, line 2: "2,TALES OF SHIVA,Mark,mark,0"

[2022-07-22 07:31:35,696] {taskinstance.py:1420} INFO - Marking task as FAILED. dag_id=etl, task_id=get_data, execution_date=20220722T073134, start_date=20220722T073135, end_date=20220722T073135
[2022-07-22 07:31:35,704] {standard_task_runner.py:97} ERROR - Failed to execute job 41 for task get_data (extra data after last expected column
CONTEXT:  COPY employees_temp, line 2: "2,TALES OF SHIVA,Mark,mark,0"
; 12778)
[2022-07-22 07:31:35,738] {local_task_job.py:156} INFO - Task exited with return code 1
[2022-07-22 07:31:35,765] {local_task_job.py:273} INFO - 0 downstream tasks scheduled from follow-on schedule check
