[2022-07-22 07:33:28,853] {taskinstance.py:1179} INFO - Dependencies all met for <TaskInstance: etl.get_data manual__2022-07-22T07:33:27.424311+00:00 [queued]>
[2022-07-22 07:33:28,859] {taskinstance.py:1179} INFO - Dependencies all met for <TaskInstance: etl.get_data manual__2022-07-22T07:33:27.424311+00:00 [queued]>
[2022-07-22 07:33:28,860] {taskinstance.py:1376} INFO - 
--------------------------------------------------------------------------------
[2022-07-22 07:33:28,861] {taskinstance.py:1377} INFO - Starting attempt 1 of 1
[2022-07-22 07:33:28,861] {taskinstance.py:1378} INFO - 
--------------------------------------------------------------------------------
[2022-07-22 07:33:28,870] {taskinstance.py:1397} INFO - Executing <Task(_PythonDecoratedOperator): get_data> on 2022-07-22 07:33:27.424311+00:00
[2022-07-22 07:33:28,874] {standard_task_runner.py:52} INFO - Started process 12897 to run task
[2022-07-22 07:33:28,876] {standard_task_runner.py:79} INFO - Running: ['***', 'tasks', 'run', 'etl', 'get_data', 'manual__2022-07-22T07:33:27.424311+00:00', '--job-id', '43', '--raw', '--subdir', 'DAGS_FOLDER/pipeline_2.py', '--cfg-path', '/tmp/tmpebpvo8qc', '--error-file', '/tmp/tmp4x1c1dwx']
[2022-07-22 07:33:28,877] {standard_task_runner.py:80} INFO - Job 43: Subtask get_data
[2022-07-22 07:33:28,920] {task_command.py:371} INFO - Running <TaskInstance: etl.get_data manual__2022-07-22T07:33:27.424311+00:00 [running]> on host b51f0a1d5848
[2022-07-22 07:33:29,008] {taskinstance.py:1591} INFO - Exporting the following env vars:
AIRFLOW_CTX_DAG_OWNER=***
AIRFLOW_CTX_DAG_ID=etl
AIRFLOW_CTX_TASK_ID=get_data
AIRFLOW_CTX_EXECUTION_DATE=2022-07-22T07:33:27.424311+00:00
AIRFLOW_CTX_TRY_NUMBER=1
AIRFLOW_CTX_DAG_RUN_ID=manual__2022-07-22T07:33:27.424311+00:00
[2022-07-22 07:33:29,147] {base.py:68} INFO - Using connection ID 'pg' for task execution.
[2022-07-22 07:33:29,160] {taskinstance.py:1909} ERROR - Task failed with exception
Traceback (most recent call last):
  File "/home/airflow/.local/lib/python3.7/site-packages/airflow/decorators/base.py", line 179, in execute
    return_value = super().execute(context)
  File "/home/airflow/.local/lib/python3.7/site-packages/airflow/operators/python.py", line 171, in execute
    return_value = self.execute_callable()
  File "/home/airflow/.local/lib/python3.7/site-packages/airflow/operators/python.py", line 189, in execute_callable
    return self.python_callable(*self.op_args, **self.op_kwargs)
  File "/opt/airflow/dags/pipeline_2.py", line 43, in get_data
    file
psycopg2.errors.BadCopyFileFormat: extra data after last expected column
CONTEXT:  COPY employees_temp, line 2: "2,TALES OF SHIVA,Mark,mark,0"

[2022-07-22 07:33:29,175] {taskinstance.py:1420} INFO - Marking task as FAILED. dag_id=etl, task_id=get_data, execution_date=20220722T073327, start_date=20220722T073328, end_date=20220722T073329
[2022-07-22 07:33:29,187] {standard_task_runner.py:97} ERROR - Failed to execute job 43 for task get_data (extra data after last expected column
CONTEXT:  COPY employees_temp, line 2: "2,TALES OF SHIVA,Mark,mark,0"
; 12897)
[2022-07-22 07:33:29,209] {local_task_job.py:156} INFO - Task exited with return code 1
[2022-07-22 07:33:29,236] {local_task_job.py:273} INFO - 0 downstream tasks scheduled from follow-on schedule check
