[2022-07-22 08:51:39,760] {taskinstance.py:1179} INFO - Dependencies all met for <TaskInstance: dag1.add_start2 scheduled__2022-05-05T00:00:00+00:00 [queued]>
[2022-07-22 08:51:39,777] {taskinstance.py:1179} INFO - Dependencies all met for <TaskInstance: dag1.add_start2 scheduled__2022-05-05T00:00:00+00:00 [queued]>
[2022-07-22 08:51:39,778] {taskinstance.py:1376} INFO - 
--------------------------------------------------------------------------------
[2022-07-22 08:51:39,780] {taskinstance.py:1377} INFO - Starting attempt 1 of 1
[2022-07-22 08:51:39,781] {taskinstance.py:1378} INFO - 
--------------------------------------------------------------------------------
[2022-07-22 08:51:39,800] {taskinstance.py:1397} INFO - Executing <Task(_DockerDecoratedOperator): add_start2> on 2022-05-05 00:00:00+00:00
[2022-07-22 08:51:39,808] {standard_task_runner.py:52} INFO - Started process 2340 to run task
[2022-07-22 08:51:39,823] {standard_task_runner.py:79} INFO - Running: ['***', 'tasks', 'run', 'dag1', 'add_start2', 'scheduled__2022-05-05T00:00:00+00:00', '--job-id', '1017', '--raw', '--subdir', 'DAGS_FOLDER/pipeline_4.py', '--cfg-path', '/tmp/tmpaev36h5t', '--error-file', '/tmp/tmpv8g8djx4']
[2022-07-22 08:51:39,824] {standard_task_runner.py:80} INFO - Job 1017: Subtask add_start2
[2022-07-22 08:51:39,923] {task_command.py:371} INFO - Running <TaskInstance: dag1.add_start2 scheduled__2022-05-05T00:00:00+00:00 [running]> on host b51f0a1d5848
[2022-07-22 08:51:40,003] {taskinstance.py:1591} INFO - Exporting the following env vars:
AIRFLOW_CTX_DAG_OWNER=***
AIRFLOW_CTX_DAG_ID=dag1
AIRFLOW_CTX_TASK_ID=add_start2
AIRFLOW_CTX_EXECUTION_DATE=2022-05-05T00:00:00+00:00
AIRFLOW_CTX_TRY_NUMBER=1
AIRFLOW_CTX_DAG_RUN_ID=scheduled__2022-05-05T00:00:00+00:00
[2022-07-22 08:51:40,045] {taskinstance.py:1909} ERROR - Task failed with exception
Traceback (most recent call last):
  File "/home/airflow/.local/lib/python3.7/site-packages/urllib3/connectionpool.py", line 710, in urlopen
    chunked=chunked,
  File "/home/airflow/.local/lib/python3.7/site-packages/urllib3/connectionpool.py", line 398, in _make_request
    conn.request(method, url, **httplib_request_kw)
  File "/usr/local/lib/python3.7/http/client.py", line 1281, in request
    self._send_request(method, url, body, headers, encode_chunked)
  File "/usr/local/lib/python3.7/http/client.py", line 1327, in _send_request
    self.endheaders(body, encode_chunked=encode_chunked)
  File "/usr/local/lib/python3.7/http/client.py", line 1276, in endheaders
    self._send_output(message_body, encode_chunked=encode_chunked)
  File "/usr/local/lib/python3.7/http/client.py", line 1036, in _send_output
    self.send(msg)
  File "/usr/local/lib/python3.7/http/client.py", line 976, in send
    self.connect()
  File "/home/airflow/.local/lib/python3.7/site-packages/docker/transport/unixconn.py", line 30, in connect
    sock.connect(self.unix_socket)
FileNotFoundError: [Errno 2] No such file or directory

During handling of the above exception, another exception occurred:

Traceback (most recent call last):
  File "/home/airflow/.local/lib/python3.7/site-packages/requests/adapters.py", line 499, in send
    timeout=timeout,
  File "/home/airflow/.local/lib/python3.7/site-packages/urllib3/connectionpool.py", line 786, in urlopen
    method, url, error=e, _pool=self, _stacktrace=sys.exc_info()[2]
  File "/home/airflow/.local/lib/python3.7/site-packages/urllib3/util/retry.py", line 550, in increment
    raise six.reraise(type(error), error, _stacktrace)
  File "/home/airflow/.local/lib/python3.7/site-packages/urllib3/packages/six.py", line 769, in reraise
    raise value.with_traceback(tb)
  File "/home/airflow/.local/lib/python3.7/site-packages/urllib3/connectionpool.py", line 710, in urlopen
    chunked=chunked,
  File "/home/airflow/.local/lib/python3.7/site-packages/urllib3/connectionpool.py", line 398, in _make_request
    conn.request(method, url, **httplib_request_kw)
  File "/usr/local/lib/python3.7/http/client.py", line 1281, in request
    self._send_request(method, url, body, headers, encode_chunked)
  File "/usr/local/lib/python3.7/http/client.py", line 1327, in _send_request
    self.endheaders(body, encode_chunked=encode_chunked)
  File "/usr/local/lib/python3.7/http/client.py", line 1276, in endheaders
    self._send_output(message_body, encode_chunked=encode_chunked)
  File "/usr/local/lib/python3.7/http/client.py", line 1036, in _send_output
    self.send(msg)
  File "/usr/local/lib/python3.7/http/client.py", line 976, in send
    self.connect()
  File "/home/airflow/.local/lib/python3.7/site-packages/docker/transport/unixconn.py", line 30, in connect
    sock.connect(self.unix_socket)
urllib3.exceptions.ProtocolError: ('Connection aborted.', FileNotFoundError(2, 'No such file or directory'))

During handling of the above exception, another exception occurred:

Traceback (most recent call last):
  File "/home/airflow/.local/lib/python3.7/site-packages/docker/api/client.py", line 214, in _retrieve_server_version
    return self.version(api_version=False)["ApiVersion"]
  File "/home/airflow/.local/lib/python3.7/site-packages/docker/api/daemon.py", line 181, in version
    return self._result(self._get(url), json=True)
  File "/home/airflow/.local/lib/python3.7/site-packages/docker/utils/decorators.py", line 46, in inner
    return f(self, *args, **kwargs)
  File "/home/airflow/.local/lib/python3.7/site-packages/docker/api/client.py", line 237, in _get
    return self.get(url, **self._set_request_timeout(kwargs))
  File "/home/airflow/.local/lib/python3.7/site-packages/requests/sessions.py", line 600, in get
    return self.request("GET", url, **kwargs)
  File "/home/airflow/.local/lib/python3.7/site-packages/requests/sessions.py", line 587, in request
    resp = self.send(prep, **send_kwargs)
  File "/home/airflow/.local/lib/python3.7/site-packages/requests/sessions.py", line 701, in send
    r = adapter.send(request, **kwargs)
  File "/home/airflow/.local/lib/python3.7/site-packages/requests/adapters.py", line 547, in send
    raise ConnectionError(err, request=request)
requests.exceptions.ConnectionError: ('Connection aborted.', FileNotFoundError(2, 'No such file or directory'))

During handling of the above exception, another exception occurred:

Traceback (most recent call last):
  File "/home/airflow/.local/lib/python3.7/site-packages/airflow/providers/docker/decorators/docker.py", line 123, in execute
    return super().execute(context)
  File "/home/airflow/.local/lib/python3.7/site-packages/airflow/decorators/base.py", line 179, in execute
    return_value = super().execute(context)
  File "/home/airflow/.local/lib/python3.7/site-packages/airflow/providers/docker/operators/docker.py", line 366, in execute
    self.cli = self._get_cli()
  File "/home/airflow/.local/lib/python3.7/site-packages/airflow/providers/docker/operators/docker.py", line 397, in _get_cli
    base_url=self.docker_url, version=self.api_version, tls=tls_config, timeout=self.timeout
  File "/home/airflow/.local/lib/python3.7/site-packages/docker/api/client.py", line 197, in __init__
    self._version = self._retrieve_server_version()
  File "/home/airflow/.local/lib/python3.7/site-packages/docker/api/client.py", line 222, in _retrieve_server_version
    f'Error while fetching server API version: {e}'
docker.errors.DockerException: Error while fetching server API version: ('Connection aborted.', FileNotFoundError(2, 'No such file or directory'))
[2022-07-22 08:51:40,058] {taskinstance.py:1420} INFO - Marking task as FAILED. dag_id=dag1, task_id=add_start2, execution_date=20220505T000000, start_date=20220722T085139, end_date=20220722T085140
[2022-07-22 08:51:40,072] {standard_task_runner.py:97} ERROR - Failed to execute job 1017 for task add_start2 (Error while fetching server API version: ('Connection aborted.', FileNotFoundError(2, 'No such file or directory')); 2340)
[2022-07-22 08:51:40,111] {local_task_job.py:156} INFO - Task exited with return code 1
[2022-07-22 08:51:40,135] {local_task_job.py:273} INFO - 0 downstream tasks scheduled from follow-on schedule check
