[2022-07-22 08:45:38,028] {taskinstance.py:1179} INFO - Dependencies all met for <TaskInstance: dag1.start scheduled__2022-01-21T00:00:00+00:00 [queued]>
[2022-07-22 08:45:38,049] {taskinstance.py:1179} INFO - Dependencies all met for <TaskInstance: dag1.start scheduled__2022-01-21T00:00:00+00:00 [queued]>
[2022-07-22 08:45:38,054] {taskinstance.py:1376} INFO - 
--------------------------------------------------------------------------------
[2022-07-22 08:45:38,056] {taskinstance.py:1377} INFO - Starting attempt 1 of 1
[2022-07-22 08:45:38,056] {taskinstance.py:1378} INFO - 
--------------------------------------------------------------------------------
[2022-07-22 08:45:38,071] {taskinstance.py:1397} INFO - Executing <Task(_PythonDecoratedOperator): start> on 2022-01-21 00:00:00+00:00
[2022-07-22 08:45:38,076] {standard_task_runner.py:52} INFO - Started process 179 to run task
[2022-07-22 08:45:38,086] {standard_task_runner.py:79} INFO - Running: ['***', 'tasks', 'run', 'dag1', 'start', 'scheduled__2022-01-21T00:00:00+00:00', '--job-id', '78', '--raw', '--subdir', 'DAGS_FOLDER/pipeline_4.py', '--cfg-path', '/tmp/tmpy89dtisg', '--error-file', '/tmp/tmp54_u0c1a']
[2022-07-22 08:45:38,087] {standard_task_runner.py:80} INFO - Job 78: Subtask start
[2022-07-22 08:45:38,159] {task_command.py:371} INFO - Running <TaskInstance: dag1.start scheduled__2022-01-21T00:00:00+00:00 [running]> on host b51f0a1d5848
[2022-07-22 08:45:38,242] {taskinstance.py:1591} INFO - Exporting the following env vars:
AIRFLOW_CTX_DAG_OWNER=***
AIRFLOW_CTX_DAG_ID=dag1
AIRFLOW_CTX_TASK_ID=start
AIRFLOW_CTX_EXECUTION_DATE=2022-01-21T00:00:00+00:00
AIRFLOW_CTX_TRY_NUMBER=1
AIRFLOW_CTX_DAG_RUN_ID=scheduled__2022-01-21T00:00:00+00:00
[2022-07-22 08:45:38,244] {taskinstance.py:1909} ERROR - Task failed with exception
Traceback (most recent call last):
  File "/home/airflow/.local/lib/python3.7/site-packages/airflow/decorators/base.py", line 179, in execute
    return_value = super().execute(context)
  File "/home/airflow/.local/lib/python3.7/site-packages/airflow/operators/python.py", line 171, in execute
    return_value = self.execute_callable()
  File "/home/airflow/.local/lib/python3.7/site-packages/airflow/operators/python.py", line 189, in execute_callable
    return self.python_callable(*self.op_args, **self.op_kwargs)
  File "/opt/airflow/dags/pipeline_4.py", line 6, in add_task
    printf(f'args: x = {x}, y = {y}')
NameError: name 'printf' is not defined
[2022-07-22 08:45:38,258] {taskinstance.py:1420} INFO - Marking task as FAILED. dag_id=dag1, task_id=start, execution_date=20220121T000000, start_date=20220722T084538, end_date=20220722T084538
[2022-07-22 08:45:38,268] {standard_task_runner.py:97} ERROR - Failed to execute job 78 for task start (name 'printf' is not defined; 179)
[2022-07-22 08:45:38,294] {local_task_job.py:156} INFO - Task exited with return code 1
[2022-07-22 08:45:38,329] {local_task_job.py:273} INFO - 0 downstream tasks scheduled from follow-on schedule check
